Workbook
Name DatumSvatby: 'Přehled'!$C$8
Name Rozpocet: 'Přehled'!$C$9

Sheet Přehled
B2: Svatební plánovač
B3: Vyplňte zelená pole, zbytek se spočítá sám. Návod najdete v posledním listu.
B5: Základní údaje | F5: Odpočet
B6: Nevěsta | C6: Tereza | F6: Do svatby zbývá | G6: =IF(ISNUMBER(DatumSvatby),MAX(0,DatumSvatby-TODAY()),"–") | H6: =IF(ISNUMBER(G6),IF(G6=1,"den",IF(AND(G6>=2,G6<=4),"dny","dní")),"")
B7: Ženich | C7: Jakub | F7: Svatba připadá na | G7: =IF(ISNUMBER(DatumSvatby),CHOOSE(WEEKDAY(DatumSvatby,2),"pondělí","úterý","středa","čtvrtek","pátek","sobotu","neděli"),"")
B8: Datum svatby | C8: 46550 | F8: Hotové úkoly | G8: =IFERROR(COUNTIF('Úkoly'!$E$5:$E$89,"Hotovo")/COUNTA('Úkoly'!$B$5:$B$89),0)
B9: Celkový rozpočet | C9: 280000 | G9: =REPT("■",ROUND(MIN(1,MAX(0,G8))*20,0))&REPT("□",20-ROUND(MIN(1,MAX(0,G8))*20,0))
B11: Rozpočet | F11: Hosté (počet osob)
B12: Počítá se s (plán nebo skutečná cena) | C12: =SUM('Rozpočet'!$F$5:$F$89) | F12: Pozvaní na obřad a hostinu | G12: =SUMIFS('Hosté'!$D$5:$D$254,'Hosté'!$F$5:$F$254,"Obřad a hostina")
B13: Zbývá z rozpočtu | C13: =IF(N(Rozpocet)=0,"–",Rozpocet-C12) | F13: Pozvaní jen na večer | G13: =SUMIFS('Hosté'!$D$5:$D$254,'Hosté'!$F$5:$F$254,"Jen večer")
B14: Už zaplaceno | C14: =SUM('Rozpočet'!$E$5:$E$89) | F14: Potvrzeno | G14: =SUMIFS('Hosté'!$D$5:$D$254,'Hosté'!$H$5:$H$254,"Potvrzeno")
B15: Zbývá doplatit | C15: =SUM('Rozpočet'!$G$5:$G$89) | F15: Odmítnuto | G15: =SUMIFS('Hosté'!$D$5:$D$254,'Hosté'!$H$5:$H$254,"Odmítnuto")
B16: Čerpání rozpočtu | C16: =IF(N(Rozpocet)=0,0,C12/Rozpocet) | F16: Čeká na odpověď | G16: =SUMIFS('Hosté'!$D$5:$D$254,'Hosté'!$F$5:$F$254,"<>Jen oznámení",'Hosté'!$F$5:$F$254,"<>",'Hosté'!$H$5:$H$254,"<>Potvrzeno",'Hosté'!$H$5:$H$254,"<>Odmítnuto")
C17: =REPT("■",ROUND(MIN(1,MAX(0,C16))*20,0))&REPT("□",20-ROUND(MIN(1,MAX(0,C16))*20,0)) | F17: Z potvrzených dětí | G17: =SUMIFS('Hosté'!$E$5:$E$254,'Hosté'!$H$5:$H$254,"Potvrzeno")
F18: Z potvrzených se speciální stravou | G18: =SUMIFS('Hosté'!$D$5:$D$254,'Hosté'!$H$5:$H$254,"Potvrzeno",'Hosté'!$I$5:$I$254,"<>Bez omezení",'Hosté'!$I$5:$I$254,"<>")
F19: Potvrzení bez stolu | G19: =SUMIFS('Hosté'!$D$5:$D$254,'Hosté'!$H$5:$H$254,"Potvrzeno",'Hosté'!$K$5:$K$254,"")
B21: Nejbližší úkoly | F21: Nejbližší platby
B22: Úkol | C22: Termín | F22: Položka | G22: Splatnost | H22: Doplatit
B23: =IFERROR(INDEX('Úkoly'!$B$5:$B$89,MATCH(SMALL('Úkoly'!$H$5:$H$89,1),'Úkoly'!$H$5:$H$89,0)),IF(ISNUMBER(DatumSvatby),"Všechno hotovo","Vyplňte datum svatby")) | C23: =IFERROR(INT(SMALL('Úkoly'!$H$5:$H$89,1)),"") | F23: =IFERROR(INDEX('Rozpočet'!$B$5:$B$89,MATCH(SMALL('Rozpočet'!$Z$5:$Z$89,1),'Rozpočet'!$Z$5:$Z$89,0)),"Žádné naplánované platby") | G23: =IFERROR(INT(SMALL('Rozpočet'!$Z$5:$Z$89,1)),"") | H23: =IFERROR(INDEX('Rozpočet'!$G$5:$G$89,MATCH(SMALL('Rozpočet'!$Z$5:$Z$89,1),'Rozpočet'!$Z$5:$Z$89,0)),"")
B24: =IFERROR(INDEX('Úkoly'!$B$5:$B$89,MATCH(SMALL('Úkoly'!$H$5:$H$89,2),'Úkoly'!$H$5:$H$89,0)),IF(ISNUMBER(DatumSvatby),"","")) | C24: =IFERROR(INT(SMALL('Úkoly'!$H$5:$H$89,2)),"") | F24: =IFERROR(INDEX('Rozpočet'!$B$5:$B$89,MATCH(SMALL('Rozpočet'!$Z$5:$Z$89,2),'Rozpočet'!$Z$5:$Z$89,0)),"") | G24: =IFERROR(INT(SMALL('Rozpočet'!$Z$5:$Z$89,2)),"") | H24: =IFERROR(INDEX('Rozpočet'!$G$5:$G$89,MATCH(SMALL('Rozpočet'!$Z$5:$Z$89,2),'Rozpočet'!$Z$5:$Z$89,0)),"")
B25: =IFERROR(INDEX('Úkoly'!$B$5:$B$89,MATCH(SMALL('Úkoly'!$H$5:$H$89,3),'Úkoly'!$H$5:$H$89,0)),IF(ISNUMBER(DatumSvatby),"","")) | C25: =IFERROR(INT(SMALL('Úkoly'!$H$5:$H$89,3)),"") | F25: =IFERROR(INDEX('Rozpočet'!$B$5:$B$89,MATCH(SMALL('Rozpočet'!$Z$5:$Z$89,3),'Rozpočet'!$Z$5:$Z$89,0)),"") | G25: =IFERROR(INT(SMALL('Rozpočet'!$Z$5:$Z$89,3)),"") | H25: =IFERROR(INDEX('Rozpočet'!$G$5:$G$89,MATCH(SMALL('Rozpočet'!$Z$5:$Z$89,3),'Rozpočet'!$Z$5:$Z$89,0)),"")
B26: =IFERROR(INDEX('Úkoly'!$B$5:$B$89,MATCH(SMALL('Úkoly'!$H$5:$H$89,4),'Úkoly'!$H$5:$H$89,0)),IF(ISNUMBER(DatumSvatby),"","")) | C26: =IFERROR(INT(SMALL('Úkoly'!$H$5:$H$89,4)),"") | F26: =IFERROR(INDEX('Rozpočet'!$B$5:$B$89,MATCH(SMALL('Rozpočet'!$Z$5:$Z$89,4),'Rozpočet'!$Z$5:$Z$89,0)),"") | G26: =IFERROR(INT(SMALL('Rozpočet'!$Z$5:$Z$89,4)),"") | H26: =IFERROR(INDEX('Rozpočet'!$G$5:$G$89,MATCH(SMALL('Rozpočet'!$Z$5:$Z$89,4),'Rozpočet'!$Z$5:$Z$89,0)),"")
B27: =IFERROR(INDEX('Úkoly'!$B$5:$B$89,MATCH(SMALL('Úkoly'!$H$5:$H$89,5),'Úkoly'!$H$5:$H$89,0)),IF(ISNUMBER(DatumSvatby),"","")) | C27: =IFERROR(INT(SMALL('Úkoly'!$H$5:$H$89,5)),"") | F27: =IFERROR(INDEX('Rozpočet'!$B$5:$B$89,MATCH(SMALL('Rozpočet'!$Z$5:$Z$89,5),'Rozpočet'!$Z$5:$Z$89,0)),"") | G27: =IFERROR(INT(SMALL('Rozpočet'!$Z$5:$Z$89,5)),"") | H27: =IFERROR(INDEX('Rozpočet'!$G$5:$G$89,MATCH(SMALL('Rozpočet'!$Z$5:$Z$89,5),'Rozpočet'!$Z$5:$Z$89,0)),"")
B29: Červeně = po termínu.

Sheet Úkoly
A1: Úkoly
A2: Termíny se počítají z data svatby. Hotové označte ve sloupci Stav. Vlastní úkol přidáte do prázdného řádku: stačí napsat, kolik dní před svatbou má být hotový.
A4: Fáze | B4: Úkol | C4: Dní před svatbou | D4: Termín | E4: Stav | F4: Kdo | G4: Poznámka
A5: 12+ měsíců | B5: Ujasnit si představu: velikost svatby, styl, roční období | C5: 390 | D5: =IF(OR($C5="",NOT(ISNUMBER(DatumSvatby))),"",DatumSvatby-$C5) | E5: Hotovo | F5: Oba | H5: =IF(OR($E5="Hotovo",$D5=""),"",$D5+ROW()/100000)
A6: 12+ měsíců | B6: Stanovit celkový rozpočet a domluvit, kdo co platí | C6: 380 | D6: =IF(OR($C6="",NOT(ISNUMBER(DatumSvatby))),"",DatumSvatby-$C6) | E6: Hotovo | H6: =IF(OR($E6="Hotovo",$D6=""),"",$D6+ROW()/100000)
A7: 12+ měsíců | B7: Sepsat první seznam hostů (hrubý odhad počtu) | C7: 370 | D7: =IF(OR($C7="",NOT(ISNUMBER(DatumSvatby))),"",DatumSvatby-$C7) | E7: Hotovo | H7: =IF(OR($E7="Hotovo",$D7=""),"",$D7+ROW()/100000)
A8: 12+ měsíců | B8: Vybrat termín a 2–3 náhradní | C8: 365 | D8: =IF(OR($C8="",NOT(ISNUMBER(DatumSvatby))),"",DatumSvatby-$C8) | E8: Hotovo | F8: Oba | H8: =IF(OR($E8="Hotovo",$D8=""),"",$D8+ROW()/100000)
A9: 12+ měsíců | B9: Vybrat a rezervovat místo obřadu i hostiny | C9: 350 | D9: =IF(OR($C9="",NOT(ISNUMBER(DatumSvatby))),"",DatumSvatby-$C9) | E9: Hotovo | H9: =IF(OR($E9="Hotovo",$D9=""),"",$D9+ROW()/100000)
A10: 12+ měsíců | B10: Zjistit na matrice doklady, lhůty a poplatky pro váš termín a místo | C10: 345 | D10: =IF(OR($C10="",NOT(ISNUMBER(DatumSvatby))),"",DatumSvatby-$C10) | E10: Hotovo | H10: =IF(OR($E10="Hotovo",$D10=""),"",$D10+ROW()/100000)
A11: 12+ měsíců | B11: Domluvit oddávajícího (matrika, církev, obřadník) | C11: 340 | D11: =IF(OR($C11="",NOT(ISNUMBER(DatumSvatby))),"",DatumSvatby-$C11) | E11: Hotovo | F11: Oba | H11: =IF(OR($E11="Hotovo",$D11=""),"",$D11+ROW()/100000)
A12: 12+ měsíců | B12: Vybrat a rezervovat fotografa | C12: 330 | D12: =IF(OR($C12="",NOT(ISNUMBER(DatumSvatby))),"",DatumSvatby-$C12) | E12: Hotovo | H12: =IF(OR($E12="Hotovo",$D12=""),"",$D12+ROW()/100000)
A13: 12+ měsíců | B13: Vybrat a rezervovat kameramana | C13: 320 | D13: =IF(OR($C13="",NOT(ISNUMBER(DatumSvatby))),"",DatumSvatby-$C13) | E13: Hotovo | H13: =IF(OR($E13="Hotovo",$D13=""),"",$D13+ROW()/100000)
A14: 9–12 měsíců | B14: Vybrat a požádat svědky | C14: 300 | D14: =IF(OR($C14="",NOT(ISNUMBER(DatumSvatby))),"",DatumSvatby-$C14) | E14: Hotovo | F14: Oba | H14: =IF(OR($E14="Hotovo",$D14=""),"",$D14+ROW()/100000)
A15: 9–12 měsíců | B15: Rezervovat kapelu nebo DJ | C15: 290 | D15: =IF(OR($C15="",NOT(ISNUMBER(DatumSvatby))),"",DatumSvatby-$C15) | E15: Hotovo | H15: =IF(OR($E15="Hotovo",$D15=""),"",$D15+ROW()/100000)
A16: 9–12 měsíců | B16: Rezervovat catering (pokud není součástí místa) | C16: 285 | D16: =IF(OR($C16="",NOT(ISNUMBER(DatumSvatby))),"",DatumSvatby-$C16) | E16: Hotovo | H16: =IF(OR($E16="Hotovo",$D16=""),"",$D16+ROW()/100000)
A17: 9–12 měsíců | B17: Poslat „save the date“ hostům, kteří cestují zdaleka | C17: 280 | D17: =IF(OR($C17="",NOT(ISNUMBER(DatumSvatby))),"",DatumSvatby-$C17) | E17: Hotovo | F17: Oba | H17: =IF(OR($E17="Hotovo",$D17=""),"",$D17+ROW()/100000)
A18: 9–12 měsíců | B18: Sjednotit styl svatby (barvy, výzdoba, nástěnka s inspirací) | C18: 275 | D18: =IF(OR($C18="",NOT(ISNUMBER(DatumSvatby))),"",DatumSvatby-$C18) | E18: Hotovo | H18: =IF(OR($E18="Hotovo",$D18=""),"",$D18+ROW()/100000)
A19: 6–9 měsíců | B19: Začít vybírat svatební šaty | C19: 250 | D19: =IF(OR($C19="",NOT(ISNUMBER(DatumSvatby))),"",DatumSvatby-$C19) | E19: Rozpracováno | H19: =IF(OR($E19="Hotovo",$D19=""),"",$D19+ROW()/100000)
A20: 6–9 měsíců | B20: Rezervovat floristku a výzdobu | C20: 230 | D20: =IF(OR($C20="",NOT(ISNUMBER(DatumSvatby))),"",DatumSvatby-$C20) | F20: Oba | H20: =IF(OR($E20="Hotovo",$D20=""),"",$D20+ROW()/100000)
A21: 6–9 měsíců | B21: Rezervovat kadeřnici a vizážistku | C21: 220 | D21: =IF(OR($C21="",NOT(ISNUMBER(DatumSvatby))),"",DatumSvatby-$C21) | H21: =IF(OR($E21="Hotovo",$D21=""),"",$D21+ROW()/100000)
A22: 6–9 měsíců | B22: Zajistit ubytování pro hosty | C22: 210 | D22: =IF(OR($C22="",NOT(ISNUMBER(DatumSvatby))),"",DatumSvatby-$C22) | H22: =IF(OR($E22="Hotovo",$D22=""),"",$D22+ROW()/100000)
A23: 6–9 měsíců | B23: Naplánovat svatební cestu, zkontrolovat platnost pasů | C23: 200 | D23: =IF(OR($C23="",NOT(ISNUMBER(DatumSvatby))),"",DatumSvatby-$C23) | F23: Oba | H23: =IF(OR($E23="Hotovo",$D23=""),"",$D23+ROW()/100000)
A24: 6–9 měsíců | B24: Vybrat oblek pro ženicha | C24: 190 | D24: =IF(OR($C24="",NOT(ISNUMBER(DatumSvatby))),"",DatumSvatby-$C24) | H24: =IF(OR($E24="Hotovo",$D24=""),"",$D24+ROW()/100000)
A25: 6–9 měsíců | B25: Rezervovat dopravu (svatební auto, autobus pro hosty) | C25: 185 | D25: =IF(OR($C25="",NOT(ISNUMBER(DatumSvatby))),"",DatumSvatby-$C25) | H25: =IF(OR($E25="Hotovo",$D25=""),"",$D25+ROW()/100000)
A26: 3–6 měsíců | B26: Objednat snubní prsteny | C26: 160 | D26: =IF(OR($C26="",NOT(ISNUMBER(DatumSvatby))),"",DatumSvatby-$C26) | F26: Oba | H26: =IF(OR($E26="Hotovo",$D26=""),"",$D26+ROW()/100000)
A27: 3–6 měsíců | B27: Objednat svatební oznámení a pozvánky na hostinu | C27: 150 | D27: =IF(OR($C27="",NOT(ISNUMBER(DatumSvatby))),"",DatumSvatby-$C27) | H27: =IF(OR($E27="Hotovo",$D27=""),"",$D27+ROW()/100000)
A28: 3–6 měsíců | B28: Objednat svatební dort a koláčky | C28: 130 | D28: =IF(OR($C28="",NOT(ISNUMBER(DatumSvatby))),"",DatumSvatby-$C28) | H28: =IF(OR($E28="Hotovo",$D28=""),"",$D28+ROW()/100000)
A29: 3–6 měsíců | B29: Ochutnávka menu a výběr jídla | C29: 110 | D29: =IF(OR($C29="",NOT(ISNUMBER(DatumSvatby))),"",DatumSvatby-$C29) | F29: Oba | H29: =IF(OR($E29="Hotovo",$D29=""),"",$D29+ROW()/100000)
A30: 3–6 měsíců | B30: Rozeslat oznámení a pozvánky | C30: 100 | D30: =IF(OR($C30="",NOT(ISNUMBER(DatumSvatby))),"",DatumSvatby-$C30) | H30: =IF(OR($E30="Hotovo",$D30=""),"",$D30+ROW()/100000)
A31: 3–6 měsíců | B31: Domluvit program: proslovy, hry, první tanec | C31: 95 | D31: =IF(OR($C31="",NOT(ISNUMBER(DatumSvatby))),"",DatumSvatby-$C31) | H31: =IF(OR($E31="Hotovo",$D31=""),"",$D31+ROW()/100000)
A32: 3–6 měsíců | B32: Zkouška účesu a líčení | C32: 90 | D32: =IF(OR($C32="",NOT(ISNUMBER(DatumSvatby))),"",DatumSvatby-$C32) | F32: Oba | H32: =IF(OR($E32="Hotovo",$D32=""),"",$D32+ROW()/100000)
A33: 1–3 měsíce | B33: Podat na matrice dotazník k uzavření manželství s doklady | C33: 75 | D33: =IF(OR($C33="",NOT(ISNUMBER(DatumSvatby))),"",DatumSvatby-$C33) | H33: =IF(OR($E33="Hotovo",$D33=""),"",$D33+ROW()/100000)
A34: 1–3 měsíce | B34: Rozhodnout o příjmení po svatbě (uvádí se v dotazníku) | C34: 75 | D34: =IF(OR($C34="",NOT(ISNUMBER(DatumSvatby))),"",DatumSvatby-$C34) | H34: =IF(OR($E34="Hotovo",$D34=""),"",$D34+ROW()/100000)
A35: 1–3 měsíce | B35: Nacvičit první tanec | C35: 60 | D35: =IF(OR($C35="",NOT(ISNUMBER(DatumSvatby))),"",DatumSvatby-$C35) | F35: Oba | H35: =IF(OR($E35="Hotovo",$D35=""),"",$D35+ROW()/100000)
A36: 1–3 měsíce | B36: Koupit doplňky: boty, závoj, kravata, podvazek | C36: 50 | D36: =IF(OR($C36="",NOT(ISNUMBER(DatumSvatby))),"",DatumSvatby-$C36) | H36: =IF(OR($E36="Hotovo",$D36=""),"",$D36+ROW()/100000)
A37: 1–3 měsíce | B37: Doplatit zálohy podle smluv s dodavateli | C37: 45 | D37: =IF(OR($C37="",NOT(ISNUMBER(DatumSvatby))),"",DatumSvatby-$C37) | H37: =IF(OR($E37="Hotovo",$D37=""),"",$D37+ROW()/100000)
A38: 1–3 měsíce | B38: Zkouška šatů a úpravy | C38: 40 | D38: =IF(OR($C38="",NOT(ISNUMBER(DatumSvatby))),"",DatumSvatby-$C38) | F38: Oba | H38: =IF(OR($E38="Hotovo",$D38=""),"",$D38+ROW()/100000)
A39: 1–3 měsíce | B39: Připomenout se hostům, kteří neodpověděli | C39: 35 | D39: =IF(OR($C39="",NOT(ISNUMBER(DatumSvatby))),"",DatumSvatby-$C39) | H39: =IF(OR($E39="Hotovo",$D39=""),"",$D39+ROW()/100000)
A40: 1–3 měsíce | B40: Sepsat harmonogram dne D a poslat ho dodavatelům | C40: 35 | D40: =IF(OR($C40="",NOT(ISNUMBER(DatumSvatby))),"",DatumSvatby-$C40) | H40: =IF(OR($E40="Hotovo",$D40=""),"",$D40+ROW()/100000)
A41: 1–3 měsíce | B41: Nahlásit konečný počet hostů místu a cateringu | C41: 30 | D41: =IF(OR($C41="",NOT(ISNUMBER(DatumSvatby))),"",DatumSvatby-$C41) | F41: Oba | H41: =IF(OR($E41="Hotovo",$D41=""),"",$D41+ROW()/100000)
...

Sheet Rozpočet
A1: Rozpočet
A2: Napište plán. Jakmile znáte skutečnou cenu, doplňte ji a plánovač začne počítat s ní. Zálohy a platby zapisujte do sloupce Zaplaceno.
A4: Kategorie | B4: Položka | C4: Plán | D4: Skutečná cena | E4: Zaplaceno | F4: Počítá se s | G4: Zbývá doplatit | H4: Splatnost | I4: Dodavatel | J4: Poznámka | L4: Kategorie | M4: Doporučený podíl | N4: Doporučeno | O4: Plán | P4: Počítá se s | Q4: Rozdíl
A5: Místo a hostina | B5: Pronájem prostor | C5: 25000 | D5: 25000 | E5: 10000 | F5: =IF(AND($C5="",$D5=""),"",IF($D5<>"",$D5,N($C5))) | G5: =IF($F5="","",MAX(0,$F5-N($E5))) | H5: 46490 | I5: Statek Na Kopci | L5: Místo a hostina | M5: 0.4 | N5: =$M5*N(Rozpocet) | O5: =SUMIFS($C$5:$C$89,$A$5:$A$89,$L5) | P5: =SUMIFS($F$5:$F$89,$A$5:$A$89,$L5) | Q5: =N5-P5 | Z5: =IF(OR($H5="",N($G5)<=0),"",$H5+ROW()/100000)
A6: Místo a hostina | B6: Svatební oběd | C6: 36000 | F6: =IF(AND($C6="",$D6=""),"",IF($D6<>"",$D6,N($C6))) | G6: =IF($F6="","",MAX(0,$F6-N($E6))) | H6: 46536 | I6: Statek Na Kopci | L6: Foto a video | M6: 0.12 | N6: =$M6*N(Rozpocet) | O6: =SUMIFS($C$5:$C$89,$A$5:$A$89,$L6) | P6: =SUMIFS($F$5:$F$89,$A$5:$A$89,$L6) | Q6: =N6-P6 | Z6: =IF(OR($H6="",N($G6)<=0),"",$H6+ROW()/100000)
A7: Místo a hostina | B7: Večerní raut | C7: 18000 | F7: =IF(AND($C7="",$D7=""),"",IF($D7<>"",$D7,N($C7))) | G7: =IF($F7="","",MAX(0,$F7-N($E7))) | H7: 46536 | I7: Statek Na Kopci | L7: Oblečení a doplňky | M7: 0.09 | N7: =$M7*N(Rozpocet) | O7: =SUMIFS($C$5:$C$89,$A$5:$A$89,$L7) | P7: =SUMIFS($F$5:$F$89,$A$5:$A$89,$L7) | Q7: =N7-P7 | Z7: =IF(OR($H7="",N($G7)<=0),"",$H7+ROW()/100000)
A8: Místo a hostina | B8: Nápoje | C8: 20000 | F8: =IF(AND($C8="",$D8=""),"",IF($D8<>"",$D8,N($C8))) | G8: =IF($F8="","",MAX(0,$F8-N($E8))) | H8: 46536 | I8: Statek Na Kopci | L8: Prsteny | M8: 0.07 | N8: =$M8*N(Rozpocet) | O8: =SUMIFS($C$5:$C$89,$A$5:$A$89,$L8) | P8: =SUMIFS($F$5:$F$89,$A$5:$A$89,$L8) | Q8: =N8-P8 | Z8: =IF(OR($H8="",N($G8)<=0),"",$H8+ROW()/100000)
A9: Foto a video | B9: Fotograf | C9: 30000 | D9: 32000 | E9: 10000 | F9: =IF(AND($C9="",$D9=""),"",IF($D9<>"",$D9,N($C9))) | G9: =IF($F9="","",MAX(0,$F9-N($E9))) | H9: 46520 | I9: Foto Jan Dvořák | L9: Hudba a zábava | M9: 0.07 | N9: =$M9*N(Rozpocet) | O9: =SUMIFS($C$5:$C$89,$A$5:$A$89,$L9) | P9: =SUMIFS($F$5:$F$89,$A$5:$A$89,$L9) | Q9: =N9-P9 | Z9: =IF(OR($H9="",N($G9)<=0),"",$H9+ROW()/100000)
A10: Foto a video | B10: Kameraman | C10: 25000 | F10: =IF(AND($C10="",$D10=""),"",IF($D10<>"",$D10,N($C10))) | G10: =IF($F10="","",MAX(0,$F10-N($E10))) | L10: Květiny a výzdoba | M10: 0.07 | N10: =$M10*N(Rozpocet) | O10: =SUMIFS($C$5:$C$89,$A$5:$A$89,$L10) | P10: =SUMIFS($F$5:$F$89,$A$5:$A$89,$L10) | Q10: =N10-P10 | Z10: =IF(OR($H10="",N($G10)<=0),"",$H10+ROW()/100000)
A11: Oblečení a doplňky | B11: Svatební šaty | C11: 18000 | D11: 21500 | E11: 21500 | F11: =IF(AND($C11="",$D11=""),"",IF($D11<>"",$D11,N($C11))) | G11: =IF($F11="","",MAX(0,$F11-N($E11))) | I11: Salon Bílá | L11: Dort a sladkosti | M11: 0.03 | N11: =$M11*N(Rozpocet) | O11: =SUMIFS($C$5:$C$89,$A$5:$A$89,$L11) | P11: =SUMIFS($F$5:$F$89,$A$5:$A$89,$L11) | Q11: =N11-P11 | Z11: =IF(OR($H11="",N($G11)<=0),"",$H11+ROW()/100000)
A12: Oblečení a doplňky | B12: Boty a doplňky nevěsty | C12: 3000 | F12: =IF(AND($C12="",$D12=""),"",IF($D12<>"",$D12,N($C12))) | G12: =IF($F12="","",MAX(0,$F12-N($E12))) | L12: Vlasy a líčení | M12: 0.02 | N12: =$M12*N(Rozpocet) | O12: =SUMIFS($C$5:$C$89,$A$5:$A$89,$L12) | P12: =SUMIFS($F$5:$F$89,$A$5:$A$89,$L12) | Q12: =N12-P12 | Z12: =IF(OR($H12="",N($G12)<=0),"",$H12+ROW()/100000)
A13: Oblečení a doplňky | B13: Oblek ženicha | C13: 8000 | F13: =IF(AND($C13="",$D13=""),"",IF($D13<>"",$D13,N($C13))) | G13: =IF($F13="","",MAX(0,$F13-N($E13))) | L13: Oznámení a tiskoviny | M13: 0.02 | N13: =$M13*N(Rozpocet) | O13: =SUMIFS($C$5:$C$89,$A$5:$A$89,$L13) | P13: =SUMIFS($F$5:$F$89,$A$5:$A$89,$L13) | Q13: =N13-P13 | Z13: =IF(OR($H13="",N($G13)<=0),"",$H13+ROW()/100000)
A14: Oblečení a doplňky | B14: Boty a doplňky ženicha | C14: 2500 | F14: =IF(AND($C14="",$D14=""),"",IF($D14<>"",$D14,N($C14))) | G14: =IF($F14="","",MAX(0,$F14-N($E14))) | L14: Doprava | M14: 0.02 | N14: =$M14*N(Rozpocet) | O14: =SUMIFS($C$5:$C$89,$A$5:$A$89,$L14) | P14: =SUMIFS($F$5:$F$89,$A$5:$A$89,$L14) | Q14: =N14-P14 | Z14: =IF(OR($H14="",N($G14)<=0),"",$H14+ROW()/100000)
A15: Prsteny | B15: Snubní prsteny | C15: 18000 | F15: =IF(AND($C15="",$D15=""),"",IF($D15<>"",$D15,N($C15))) | G15: =IF($F15="","",MAX(0,$F15-N($E15))) | H15: 46505 | L15: Obřad a poplatky | M15: 0.02 | N15: =$M15*N(Rozpocet) | O15: =SUMIFS($C$5:$C$89,$A$5:$A$89,$L15) | P15: =SUMIFS($F$5:$F$89,$A$5:$A$89,$L15) | Q15: =N15-P15 | Z15: =IF(OR($H15="",N($G15)<=0),"",$H15+ROW()/100000)
A16: Hudba a zábava | B16: Kapela / DJ | C16: 15000 | D16: 14000 | E16: 5000 | F16: =IF(AND($C16="",$D16=""),"",IF($D16<>"",$D16,N($C16))) | G16: =IF($F16="","",MAX(0,$F16-N($E16))) | H16: 46543 | I16: DJ Martin | L16: Dárky | M16: 0.02 | N16: =$M16*N(Rozpocet) | O16: =SUMIFS($C$5:$C$89,$A$5:$A$89,$L16) | P16: =SUMIFS($F$5:$F$89,$A$5:$A$89,$L16) | Q16: =N16-P16 | Z16: =IF(OR($H16="",N($G16)<=0),"",$H16+ROW()/100000)
A17: Hudba a zábava | B17: Hudba na obřad | C17: 3000 | F17: =IF(AND($C17="",$D17=""),"",IF($D17<>"",$D17,N($C17))) | G17: =IF($F17="","",MAX(0,$F17-N($E17))) | L17: Rezerva | M17: 0.05 | N17: =$M17*N(Rozpocet) | O17: =SUMIFS($C$5:$C$89,$A$5:$A$89,$L17) | P17: =SUMIFS($F$5:$F$89,$A$5:$A$89,$L17) | Q17: =N17-P17 | Z17: =IF(OR($H17="",N($G17)<=0),"",$H17+ROW()/100000)
A18: Květiny a výzdoba | B18: Kytice nevěsty | C18: 2500 | F18: =IF(AND($C18="",$D18=""),"",IF($D18<>"",$D18,N($C18))) | G18: =IF($F18="","",MAX(0,$F18-N($E18))) | L18: Svatební cesta | M18: 0 | N18: =$M18*N(Rozpocet) | O18: =SUMIFS($C$5:$C$89,$A$5:$A$89,$L18) | P18: =SUMIFS($F$5:$F$89,$A$5:$A$89,$L18) | Q18: =N18-P18 | Z18: =IF(OR($H18="",N($G18)<=0),"",$H18+ROW()/100000)
A19: Květiny a výzdoba | B19: Korsáže a kytičky pro svědky | C19: 1200 | F19: =IF(AND($C19="",$D19=""),"",IF($D19<>"",$D19,N($C19))) | G19: =IF($F19="","",MAX(0,$F19-N($E19))) | L19: Celkem | M19: =SUM(M5:M18) | N19: =SUM(N5:N18) | O19: =SUM(O5:O18) | P19: =SUM(P5:P18) | Q19: =SUM(Q5:Q18) | Z19: =IF(OR($H19="",N($G19)<=0),"",$H19+ROW()/100000)
A20: Květiny a výzdoba | B20: Výzdoba obřadu | C20: 6000 | F20: =IF(AND($C20="",$D20=""),"",IF($D20<>"",$D20,N($C20))) | G20: =IF($F20="","",MAX(0,$F20-N($E20))) | Z20: =IF(OR($H20="",N($G20)<=0),"",$H20+ROW()/100000)
A21: Květiny a výzdoba | B21: Výzdoba stolů | C21: 7000 | F21: =IF(AND($C21="",$D21=""),"",IF($D21<>"",$D21,N($C21))) | G21: =IF($F21="","",MAX(0,$F21-N($E21))) | L21: Doporučený podíl je orientační rozdělení podle běžné praxe českých svateb. Klidně ho přepište podle sebe. Rozdíl = doporučeno − počítá se s. | Z21: =IF(OR($H21="",N($G21)<=0),"",$H21+ROW()/100000)
A22: Dort a sladkosti | B22: Svatební dort | C22: 5000 | F22: =IF(AND($C22="",$D22=""),"",IF($D22<>"",$D22,N($C22))) | G22: =IF($F22="","",MAX(0,$F22-N($E22))) | H22: 46543 | Z22: =IF(OR($H22="",N($G22)<=0),"",$H22+ROW()/100000)
A23: Dort a sladkosti | B23: Svatební koláčky | C23: 3000 | F23: =IF(AND($C23="",$D23=""),"",IF($D23<>"",$D23,N($C23))) | G23: =IF($F23="","",MAX(0,$F23-N($E23))) | Z23: =IF(OR($H23="",N($G23)<=0),"",$H23+ROW()/100000)
A24: Vlasy a líčení | B24: Kadeřnice a vizážistka | C24: 5000 | F24: =IF(AND($C24="",$D24=""),"",IF($D24<>"",$D24,N($C24))) | G24: =IF($F24="","",MAX(0,$F24-N($E24))) | Z24: =IF(OR($H24="",N($G24)<=0),"",$H24+ROW()/100000)
A25: Oznámení a tiskoviny | B25: Oznámení a pozvánky | C25: 3500 | D25: 3200 | E25: 3200 | F25: =IF(AND($C25="",$D25=""),"",IF($D25<>"",$D25,N($C25))) | G25: =IF($F25="","",MAX(0,$F25-N($E25))) | I25: Tiskárna Papírek | Z25: =IF(OR($H25="",N($G25)<=0),"",$H25+ROW()/100000)
A26: Oznámení a tiskoviny | B26: Jmenovky, menu, tabule | C26: 1500 | F26: =IF(AND($C26="",$D26=""),"",IF($D26<>"",$D26,N($C26))) | G26: =IF($F26="","",MAX(0,$F26-N($E26))) | Z26: =IF(OR($H26="",N($G26)<=0),"",$H26+ROW()/100000)
A27: Doprava | B27: Svatební auto | C27: 3000 | F27: =IF(AND($C27="",$D27=""),"",IF($D27<>"",$D27,N($C27))) | G27: =IF($F27="","",MAX(0,$F27-N($E27))) | Z27: =IF(OR($H27="",N($G27)<=0),"",$H27+ROW()/100000)
A28: Doprava | B28: Doprava hostů | C28: 4000 | F28: =IF(AND($C28="",$D28=""),"",IF($D28<>"",$D28,N($C28))) | G28: =IF($F28="","",MAX(0,$F28-N($E28))) | Z28: =IF(OR($H28="",N($G28)<=0),"",$H28+ROW()/100000)
A29: Obřad a poplatky | B29: Poplatky matrice a oddávajícímu | C29: 3000 | F29: =IF(AND($C29="",$D29=""),"",IF($D29<>"",$D29,N($C29))) | G29: =IF($F29="","",MAX(0,$F29-N($E29))) | Z29: =IF(OR($H29="",N($G29)<=0),"",$H29+ROW()/100000)
A30: Dárky | B30: Výslužka pro hosty | C30: 3000 | F30: =IF(AND($C30="",$D30=""),"",IF($D30<>"",$D30,N($C30))) | G30: =IF($F30="","",MAX(0,$F30-N($E30))) | Z30: =IF(OR($H30="",N($G30)<=0),"",$H30+ROW()/100000)
A31: Dárky | B31: Dárky pro rodiče a svědky | C31: 3000 | F31: =IF(AND($C31="",$D31=""),"",IF($D31<>"",$D31,N($C31))) | G31: =IF($F31="","",MAX(0,$F31-N($E31))) | Z31: =IF(OR($H31="",N($G31)<=0),"",$H31+ROW()/100000)
A32: Rezerva | B32: Nečekané výdaje | C32: 12500 | F32: =IF(AND($C32="",$D32=""),"",IF($D32<>"",$D32,N($C32))) | G32: =IF($F32="","",MAX(0,$F32-N($E32))) | Z32: =IF(OR($H32="",N($G32)<=0),"",$H32+ROW()/100000)
A33: Svatební cesta | B33: Letenky a ubytování | F33: =IF(AND($C33="",$D33=""),"",IF($D33<>"",$D33,N($C33))) | G33: =IF($F33="","",MAX(0,$F33-N($E33))) | Z33: =IF(OR($H33="",N($G33)<=0),"",$H33+ROW()/100000)
F34: =IF(AND($C34="",$D34=""),"",IF($D34<>"",$D34,N($C34))) | G34: =IF($F34="","",MAX(0,$F34-N($E34))) | Z34: =IF(OR($H34="",N($G34)<=0),"",$H34+ROW()/100000)
F35: =IF(AND($C35="",$D35=""),"",IF($D35<>"",$D35,N($C35))) | G35: =IF($F35="","",MAX(0,$F35-N($E35))) | Z35: =IF(OR($H35="",N($G35)<=0),"",$H35+ROW()/100000)
F36: =IF(AND($C36="",$D36=""),"",IF($D36<>"",$D36,N($C36))) | G36: =IF($F36="","",MAX(0,$F36-N($E36))) | Z36: =IF(OR($H36="",N($G36)<=0),"",$H36+ROW()/100000)
F37: =IF(AND($C37="",$D37=""),"",IF($D37<>"",$D37,N($C37))) | G37: =IF($F37="","",MAX(0,$F37-N($E37))) | Z37: =IF(OR($H37="",N($G37)<=0),"",$H37+ROW()/100000)
F38: =IF(AND($C38="",$D38=""),"",IF($D38<>"",$D38,N($C38))) | G38: =IF($F38="","",MAX(0,$F38-N($E38))) | Z38: =IF(OR($H38="",N($G38)<=0),"",$H38+ROW()/100000)
F39: =IF(AND($C39="",$D39=""),"",IF($D39<>"",$D39,N($C39))) | G39: =IF($F39="","",MAX(0,$F39-N($E39))) | Z39: =IF(OR($H39="",N($G39)<=0),"",$H39+ROW()/100000)
F40: =IF(AND($C40="",$D40=""),"",IF($D40<>"",$D40,N($C40))) | G40: =IF($F40="","",MAX(0,$F40-N($E40))) | Z40: =IF(OR($H40="",N($G40)<=0),"",$H40+ROW()/100000)
F41: =IF(AND($C41="",$D41=""),"",IF($D41<>"",$D41,N($C41))) | G41: =IF($F41="","",MAX(0,$F41-N($E41))) | Z41: =IF(OR($H41="",N($G41)<=0),"",$H41+ROW()/100000)
...

Sheet Hosté
A1: Hosté
A2: Jeden řádek = jedna pozvánka (domácnost). Do sloupce Osob napište, kolik lidí na ni přijde. Odpovědi zapisujte průběžně, přehled se přepočítá sám.
A4: Jméno | B4: Strana | C4: Skupina | D4: Osob | E4: Z toho děti | F4: Pozvaní na | G4: Oznámení odesláno | H4: Odpověď | I4: Strava | J4: Ubytování | K4: Stůl | L4: Adresa / kontakt | M4: Poznámka
A5: Marie a Josef Novákovi | B5: Nevěsta | C5: Rodina | D5: 2 | E5: 0 | F5: Obřad a hostina | G5: Ano | H5: Potvrzeno | I5: Bez omezení | J5: Ne | K5: 1
A6: Eva a Tomáš Svobodovi | B6: Ženich | C6: Rodina | D6: 2 | E6: 0 | F6: Obřad a hostina | G6: Ano | H6: Potvrzeno | I6: Bez omezení | J6: Ne | K6: 1
A7: Babička Anna Nováková | B7: Nevěsta | C7: Rodina | D7: 1 | E7: 0 | F7: Obřad a hostina | G7: Ano | H7: Potvrzeno | I7: Bez lepku | J7: Ano | K7: 2
A8: Petr Novák s rodinou | B8: Nevěsta | C8: Rodina | D8: 4 | E8: 2 | F8: Obřad a hostina | G8: Ano | H8: Potvrzeno | I8: Bez omezení | J8: Ano | K8: 2
A9: Jana Horáková s rodinou | B9: Nevěsta | C9: Rodina | D9: 3 | E9: 1 | F9: Obřad a hostina | G9: Ano | H9: Potvrzeno | I9: Bez omezení | J9: Ne | K9: 2
A10: Děda Karel Svoboda | B10: Ženich | C10: Rodina | D10: 1 | E10: 0 | F10: Obřad a hostina | G10: Ano | H10: Potvrzeno | I10: Bez omezení | J10: Ano | K10: 3
A11: Lucie a Martin Svobodovi | B11: Ženich | C11: Rodina | D11: 2 | E11: 0 | F11: Obřad a hostina | G11: Ano | H11: Potvrzeno | I11: Vegetarián | J11: Ano | K11: 3
A12: Kateřina Dvořáková | B12: Ženich | C12: Rodina | D12: 2 | E12: 0 | F12: Obřad a hostina | G12: Ano | H12: Čeká | J12: Ne | K12: 3
A13: Tereza Malá | B13: Nevěsta | C13: Přátelé | D13: 2 | E13: 0 | F13: Obřad a hostina | G13: Ano | H13: Potvrzeno | I13: Vegan | J13: Ano | K13: 4
A14: Barbora Černá | B14: Nevěsta | C14: Přátelé | D14: 2 | E14: 0 | F14: Obřad a hostina | G14: Ano | H14: Potvrzeno | I14: Bez omezení | J14: Ano | K14: 4
A15: Klára Veselá | B15: Nevěsta | C15: Přátelé | D15: 1 | E15: 0 | F15: Obřad a hostina | G15: Ano | H15: Čeká | J15: Ne | K15: 4
A16: Ondřej Král | B16: Ženich | C16: Přátelé | D16: 2 | E16: 0 | F16: Obřad a hostina | G16: Ano | H16: Potvrzeno | I16: Bez omezení | J16: Ano | K16: 5
A17: Jakub Beneš | B17: Ženich | C17: Přátelé | D17: 1 | E17: 0 | F17: Obřad a hostina | G17: Ano | H17: Potvrzeno | I17: Bez omezení | J17: Ano | K17: 5
A18: Michal Pokorný | B18: Ženich | C18: Přátelé | D18: 2 | E18: 0 | F18: Obřad a hostina | G18: Ano | H18: Odmítnuto | J18: Ne
A19: Adam a Nela Růžičkovi | B19: Společní | C19: Přátelé | D19: 2 | E19: 0 | F19: Obřad a hostina | G19: Ano | H19: Potvrzeno | I19: Bez laktózy | J19: Ne | K19: 5
A20: Šárka Kučerová | B20: Nevěsta | C20: Kolegové | D20: 1 | E20: 0 | F20: Jen večer | G20: Ano | H20: Potvrzeno | I20: Bez omezení | J20: Ne | K20: 6
A21: Filip Marek | B21: Ženich | C21: Kolegové | D21: 2 | E21: 0 | F21: Jen večer | G21: Ano | H21: Čeká | J21: Ne
A22: Tým z práce (Ženich) | B22: Ženich | C22: Kolegové | D22: 4 | E22: 0 | F22: Jen večer | G22: Ne | J22: Ne
A23: Sousedé Procházkovi | B23: Nevěsta | C23: Ostatní | D23: 2 | E23: 0 | F23: Jen oznámení | G23: Ano | J23: Ne
A24: Paní učitelka Hájková | B24: Nevěsta | C24: Ostatní | D24: 1 | E24: 0 | F24: Jen oznámení | G24: Ne | J24: Ne

Sheet Stoly
A1: Stoly
A2: Číslo stolu přiřaďte hostům v listu Hosté. Tady uvidíte, kolik míst je obsazeno.
A4: Stůl | B4: Popis | C4: Kapacita | D4: Obsazeno | E4: Volno | F4: Stav
A5: 1 | B5: Hlavní stůl | C5: 10 | D5: =IF($A5="","",SUMIFS('Hosté'!$D$5:$D$254,'Hosté'!$K$5:$K$254,$A5,'Hosté'!$H$5:$H$254,"<>Odmítnuto")) | E5: =IF(OR($A5="",$C5=""),"",$C5-$D5) | F5: =IF(OR($A5="",$C5=""),"",IF($D5>$C5,"Přeplněno",IF($D5=$C5,"Plno",""))) | H5: Kapacita všech stolů | I5: =SUM(C5:C29)
A6: 2 | B6: Rodina nevěsty | C6: 8 | D6: =IF($A6="","",SUMIFS('Hosté'!$D$5:$D$254,'Hosté'!$K$5:$K$254,$A6,'Hosté'!$H$5:$H$254,"<>Odmítnuto")) | E6: =IF(OR($A6="",$C6=""),"",$C6-$D6) | F6: =IF(OR($A6="",$C6=""),"",IF($D6>$C6,"Přeplněno",IF($D6=$C6,"Plno",""))) | H6: Potvrzení hosté (osob) | I6: =SUMIFS('Hosté'!$D$5:$D$254,'Hosté'!$H$5:$H$254,"Potvrzeno")
A7: 3 | B7: Rodina ženicha | C7: 8 | D7: =IF($A7="","",SUMIFS('Hosté'!$D$5:$D$254,'Hosté'!$K$5:$K$254,$A7,'Hosté'!$H$5:$H$254,"<>Odmítnuto")) | E7: =IF(OR($A7="",$C7=""),"",$C7-$D7) | F7: =IF(OR($A7="",$C7=""),"",IF($D7>$C7,"Přeplněno",IF($D7=$C7,"Plno",""))) | H7: Potvrzení hosté bez stolu | I7: =SUMIFS('Hosté'!$D$5:$D$254,'Hosté'!$H$5:$H$254,"Potvrzeno",'Hosté'!$K$5:$K$254,"")
A8: 4 | B8: Přátelé nevěsty | C8: 8 | D8: =IF($A8="","",SUMIFS('Hosté'!$D$5:$D$254,'Hosté'!$K$5:$K$254,$A8,'Hosté'!$H$5:$H$254,"<>Odmítnuto")) | E8: =IF(OR($A8="",$C8=""),"",$C8-$D8) | F8: =IF(OR($A8="",$C8=""),"",IF($D8>$C8,"Přeplněno",IF($D8=$C8,"Plno","")))
A9: 5 | B9: Přátelé ženicha | C9: 8 | D9: =IF($A9="","",SUMIFS('Hosté'!$D$5:$D$254,'Hosté'!$K$5:$K$254,$A9,'Hosté'!$H$5:$H$254,"<>Odmítnuto")) | E9: =IF(OR($A9="",$C9=""),"",$C9-$D9) | F9: =IF(OR($A9="",$C9=""),"",IF($D9>$C9,"Přeplněno",IF($D9=$C9,"Plno","")))
A10: 6 | B10: Kolegové | C10: 8 | D10: =IF($A10="","",SUMIFS('Hosté'!$D$5:$D$254,'Hosté'!$K$5:$K$254,$A10,'Hosté'!$H$5:$H$254,"<>Odmítnuto")) | E10: =IF(OR($A10="",$C10=""),"",$C10-$D10) | F10: =IF(OR($A10="",$C10=""),"",IF($D10>$C10,"Přeplněno",IF($D10=$C10,"Plno","")))
A11: 7 | B11: Děti | C11: 6 | D11: =IF($A11="","",SUMIFS('Hosté'!$D$5:$D$254,'Hosté'!$K$5:$K$254,$A11,'Hosté'!$H$5:$H$254,"<>Odmítnuto")) | E11: =IF(OR($A11="",$C11=""),"",$C11-$D11) | F11: =IF(OR($A11="",$C11=""),"",IF($D11>$C11,"Přeplněno",IF($D11=$C11,"Plno","")))
A12: 8 | D12: =IF($A12="","",SUMIFS('Hosté'!$D$5:$D$254,'Hosté'!$K$5:$K$254,$A12,'Hosté'!$H$5:$H$254,"<>Odmítnuto")) | E12: =IF(OR($A12="",$C12=""),"",$C12-$D12) | F12: =IF(OR($A12="",$C12=""),"",IF($D12>$C12,"Přeplněno",IF($D12=$C12,"Plno","")))
A13: 9 | D13: =IF($A13="","",SUMIFS('Hosté'!$D$5:$D$254,'Hosté'!$K$5:$K$254,$A13,'Hosté'!$H$5:$H$254,"<>Odmítnuto")) | E13: =IF(OR($A13="",$C13=""),"",$C13-$D13) | F13: =IF(OR($A13="",$C13=""),"",IF($D13>$C13,"Přeplněno",IF($D13=$C13,"Plno","")))
A14: 10 | D14: =IF($A14="","",SUMIFS('Hosté'!$D$5:$D$254,'Hosté'!$K$5:$K$254,$A14,'Hosté'!$H$5:$H$254,"<>Odmítnuto")) | E14: =IF(OR($A14="",$C14=""),"",$C14-$D14) | F14: =IF(OR($A14="",$C14=""),"",IF($D14>$C14,"Přeplněno",IF($D14=$C14,"Plno","")))
D15: =IF($A15="","",SUMIFS('Hosté'!$D$5:$D$254,'Hosté'!$K$5:$K$254,$A15,'Hosté'!$H$5:$H$254,"<>Odmítnuto")) | E15: =IF(OR($A15="",$C15=""),"",$C15-$D15) | F15: =IF(OR($A15="",$C15=""),"",IF($D15>$C15,"Přeplněno",IF($D15=$C15,"Plno","")))
D16: =IF($A16="","",SUMIFS('Hosté'!$D$5:$D$254,'Hosté'!$K$5:$K$254,$A16,'Hosté'!$H$5:$H$254,"<>Odmítnuto")) | E16: =IF(OR($A16="",$C16=""),"",$C16-$D16) | F16: =IF(OR($A16="",$C16=""),"",IF($D16>$C16,"Přeplněno",IF($D16=$C16,"Plno","")))
D17: =IF($A17="","",SUMIFS('Hosté'!$D$5:$D$254,'Hosté'!$K$5:$K$254,$A17,'Hosté'!$H$5:$H$254,"<>Odmítnuto")) | E17: =IF(OR($A17="",$C17=""),"",$C17-$D17) | F17: =IF(OR($A17="",$C17=""),"",IF($D17>$C17,"Přeplněno",IF($D17=$C17,"Plno","")))
D18: =IF($A18="","",SUMIFS('Hosté'!$D$5:$D$254,'Hosté'!$K$5:$K$254,$A18,'Hosté'!$H$5:$H$254,"<>Odmítnuto")) | E18: =IF(OR($A18="",$C18=""),"",$C18-$D18) | F18: =IF(OR($A18="",$C18=""),"",IF($D18>$C18,"Přeplněno",IF($D18=$C18,"Plno","")))
D19: =IF($A19="","",SUMIFS('Hosté'!$D$5:$D$254,'Hosté'!$K$5:$K$254,$A19,'Hosté'!$H$5:$H$254,"<>Odmítnuto")) | E19: =IF(OR($A19="",$C19=""),"",$C19-$D19) | F19: =IF(OR($A19="",$C19=""),"",IF($D19>$C19,"Přeplněno",IF($D19=$C19,"Plno","")))
D20: =IF($A20="","",SUMIFS('Hosté'!$D$5:$D$254,'Hosté'!$K$5:$K$254,$A20,'Hosté'!$H$5:$H$254,"<>Odmítnuto")) | E20: =IF(OR($A20="",$C20=""),"",$C20-$D20) | F20: =IF(OR($A20="",$C20=""),"",IF($D20>$C20,"Přeplněno",IF($D20=$C20,"Plno","")))
D21: =IF($A21="","",SUMIFS('Hosté'!$D$5:$D$254,'Hosté'!$K$5:$K$254,$A21,'Hosté'!$H$5:$H$254,"<>Odmítnuto")) | E21: =IF(OR($A21="",$C21=""),"",$C21-$D21) | F21: =IF(OR($A21="",$C21=""),"",IF($D21>$C21,"Přeplněno",IF($D21=$C21,"Plno","")))
D22: =IF($A22="","",SUMIFS('Hosté'!$D$5:$D$254,'Hosté'!$K$5:$K$254,$A22,'Hosté'!$H$5:$H$254,"<>Odmítnuto")) | E22: =IF(OR($A22="",$C22=""),"",$C22-$D22) | F22: =IF(OR($A22="",$C22=""),"",IF($D22>$C22,"Přeplněno",IF($D22=$C22,"Plno","")))
D23: =IF($A23="","",SUMIFS('Hosté'!$D$5:$D$254,'Hosté'!$K$5:$K$254,$A23,'Hosté'!$H$5:$H$254,"<>Odmítnuto")) | E23: =IF(OR($A23="",$C23=""),"",$C23-$D23) | F23: =IF(OR($A23="",$C23=""),"",IF($D23>$C23,"Přeplněno",IF($D23=$C23,"Plno","")))
D24: =IF($A24="","",SUMIFS('Hosté'!$D$5:$D$254,'Hosté'!$K$5:$K$254,$A24,'Hosté'!$H$5:$H$254,"<>Odmítnuto")) | E24: =IF(OR($A24="",$C24=""),"",$C24-$D24) | F24: =IF(OR($A24="",$C24=""),"",IF($D24>$C24,"Přeplněno",IF($D24=$C24,"Plno","")))
D25: =IF($A25="","",SUMIFS('Hosté'!$D$5:$D$254,'Hosté'!$K$5:$K$254,$A25,'Hosté'!$H$5:$H$254,"<>Odmítnuto")) | E25: =IF(OR($A25="",$C25=""),"",$C25-$D25) | F25: =IF(OR($A25="",$C25=""),"",IF($D25>$C25,"Přeplněno",IF($D25=$C25,"Plno","")))
D26: =IF($A26="","",SUMIFS('Hosté'!$D$5:$D$254,'Hosté'!$K$5:$K$254,$A26,'Hosté'!$H$5:$H$254,"<>Odmítnuto")) | E26: =IF(OR($A26="",$C26=""),"",$C26-$D26) | F26: =IF(OR($A26="",$C26=""),"",IF($D26>$C26,"Přeplněno",IF($D26=$C26,"Plno","")))
... D29: =IF($A29="","",SUMIFS('Hosté'!$D$5:$D$254,'Hosté'!$K$5:$K$254,$A29,'Hosté'!$H$5:$H$254,"<>Odmítnuto")) | E29: =IF(OR($A29="",$C29=""),"",$C29-$D29) | F29: =IF(OR($A29="",$C29=""),"",IF($D29>$C29,"Přeplněno",IF($D29=$C29,"Plno","")))

Sheet Dodavatelé
A1: Dodavatelé
A2: Kontakty, ceny a stav domluvy na jednom místě. Stav Zamítnuto použijte pro nabídky, které jste nevzali.
A4: Kategorie | B4: Firma / jméno | C4: Kontaktní osoba | D4: Telefon | E4: E-mail | F4: Web | G4: Cena | H4: Záloha | I4: Splatnost zálohy | J4: Smlouva | K4: Stav | L4: Poznámka
A5: Místo a hostina | B5: Statek Na Kopci | C5: Lenka Horká | D5: +420 601 111 222 | E5: info@example.cz | G5: 99000 | H5: 10000 | I5: 46490 | J5: Ano | K5: Rezervováno
A6: Foto a video | B6: Foto Jan Dvořák | C6: Jan Dvořák | D6: +420 602 333 444 | E6: jan@example.cz | G6: 32000 | H6: 10000 | I6: 46520 | J6: Ano | K6: Rezervováno
A7: Hudba a zábava | B7: DJ Martin | C7: Martin Kos | D7: +420 603 555 666 | E7: dj@example.cz | G7: 14000 | H7: 5000 | I7: 46543 | J7: Ano | K7: Rezervováno
A8: Oblečení a doplňky | B8: Salon Bílá | D8: +420 604 777 888 | G8: 21500 | H8: 21500 | J8: Ne | K8: Zaplaceno
A9: Foto a video | B9: Kamera Petr | C9: Petr Vrba | D9: +420 605 999 000 | G9: 28000 | H9: 0 | J9: Ne | K9: Poptáno

Sheet Den D
A1: Den D
A2: Harmonogram svatebního dne. Upravte ho a pošlete fotografovi, kapele i svědkům.
A4: Čas | B4: Co se děje | C4: Kde | D4: Kdo zajišťuje | E4: Poznámka
A5: 0.33333333 | B5: Snídaně a příprava nevěsty (účes, líčení) | D5: Kadeřnice, vizážistka
A6: 0.41666667 | B6: Fotograf fotí přípravy | D6: Fotograf
A7: 0.45833333 | B7: Ženich přijíždí pro nevěstu | D7: Ženich, svědci
A8: 0.47916667 | B8: Odjezd na obřad | D8: Řidič
A9: 0.5 | B9: Svatební obřad | D9: Oddávající
A10: 0.52083333 | B10: Gratulace a skupinové focení | D10: Fotograf, svědci
A11: 0.5625 | B11: Svatební oběd (rozbití talíře, krmení polévkou) | D11: Místo konání
A12: 0.625 | B12: Krájení dortu
A13: 0.64583333 | B13: Focení novomanželů | D13: Fotograf
A14: 0.70833333 | B14: Zábava a hry | D14: Svědci
A15: 0.79166667 | B15: První tanec | D15: Kapela / DJ
A16: 0.83333333 | B16: Večerní raut | D16: Catering
A17: 0.91666667 | B17: Házení kytice
A18: 0 | B18: Půlnoční překvapení, čepení nevěsty
A19: 0.083333333 | B19: Konec oslavy

Sheet Návod
B2: Jak plánovač používat
B4: Začněte tady
B5: 1. Na listu Přehled vyplňte jména, datum svatby a celkový rozpočet (zelená pole).
B6: 2. Úkoly: termíny se dopočítají podle data svatby. Hotové úkoly označte ve sloupci Stav.
B7: 3. Rozpočet: ke každé položce napište plán. Jakmile znáte skutečnou cenu, doplňte ji a plánovač začne počítat s ní.
B8: 4. Hosté: jeden řádek = jedna pozvánka. Do sloupce Osob napište, kolik lidí na ni přijde.
B9: 5. Stoly: v listu Hosté napište číslo stolu, v listu Stoly pak uvidíte obsazenost.
B10: 6. Den D: upravte harmonogram a pošlete ho fotografovi, kapele i svědkům.
B12: Tipy
B13: • Béžově podbarvené sloupce se počítají samy, nepřepisujte je.
B14: • Řádky označené „příklad“ smažte nebo přepište.
B15: • Google Tabulky: soubor nahrajte na Disk Google a otevřete v Tabulkách. Pak ho můžete sdílet s partnerem a upravovat ho oba zároveň.
... B24: Ano, beru · anoberu.cz · verze 1.0
